<?xml version="1.0" encoding="UTF-8"?>
<!-- Generated by org.testng.reporters.JUnitReportReporter -->
<testsuite hostname="INFO-LTP-014" name="com.cucumber.framework.runner.Infotech_HR.forgot_runner" tests="1" failures="0" timestamp="14 Jul 2019 05:26:05 GMT" time="70.180" errors="1">
  <testcase name="feature" time="70.180" classname="com.cucumber.framework.runner.Infotech_HR.forgot_runner">
    <error type="cucumber.runtime.CucumberException" message="java.lang.AssertionError: forgot_step is fail expected [true] but found [false]">
      <![CDATA[cucumber.runtime.CucumberException: java.lang.AssertionError: forgot_step is fail expected [true] but found [false]
	at cucumber.api.testng.TestNGCucumberRunner.runCucumber(TestNGCucumberRunner.java:69)
	at cucumber.api.testng.AbstractTestNGCucumberTests.feature(AbstractTestNGCucumberTests.java:21)
	at sun.reflect.NativeMethodAccessorImpl.invoke0(Native Method)
	at sun.reflect.NativeMethodAccessorImpl.invoke(Unknown Source)
	at sun.reflect.DelegatingMethodAccessorImpl.invoke(Unknown Source)
	at java.lang.reflect.Method.invoke(Unknown Source)
	at org.testng.internal.MethodInvocationHelper.invokeMethod(MethodInvocationHelper.java:85)
	at org.testng.internal.Invoker.invokeMethod(Invoker.java:663)
	at org.testng.internal.Invoker.invokeTestMethod(Invoker.java:849)
	at org.testng.internal.Invoker.invokeTestMethods(Invoker.java:1157)
	at org.testng.internal.TestMethodWorker.invokeTestMethods(TestMethodWorker.java:124)
	at org.testng.internal.TestMethodWorker.run(TestMethodWorker.java:108)
	at org.testng.TestRunner.privateRun(TestRunner.java:771)
	at org.testng.TestRunner.run(TestRunner.java:621)
	at org.testng.SuiteRunner.runTest(SuiteRunner.java:357)
	at org.testng.SuiteRunner.runSequentially(SuiteRunner.java:352)
	at org.testng.SuiteRunner.privateRun(SuiteRunner.java:310)
	at org.testng.SuiteRunner.run(SuiteRunner.java:259)
	at org.testng.SuiteRunnerWorker.runSuite(SuiteRunnerWorker.java:52)
	at org.testng.SuiteRunnerWorker.run(SuiteRunnerWorker.java:86)
	at org.testng.TestNG.runSuitesSequentially(TestNG.java:1200)
	at org.testng.TestNG.runSuitesLocally(TestNG.java:1125)
	at org.testng.TestNG.run(TestNG.java:1033)
	at org.testng.remote.RemoteTestNG.run(RemoteTestNG.java:111)
	at org.testng.remote.RemoteTestNG.initAndRun(RemoteTestNG.java:204)
	at org.testng.remote.RemoteTestNG.main(RemoteTestNG.java:175)
Caused by: java.lang.AssertionError: forgot_step is fail expected [true] but found [false]
	at org.testng.Assert.fail(Assert.java:94)
	at org.testng.Assert.failNotEquals(Assert.java:496)
	at org.testng.Assert.assertTrue(Assert.java:42)
	at com.cucumber.framework.stepdefinition.InfoTech_cloud.forgot_step.verify_the_succcess_alert_message_is_displayed(forgot_step.java:51)
	at âœ½.Then Verify the succcess alert message is displayed(featurefile/Infofeature/forgot_po.feature:10)
]]>
    </error>
  </testcase> <!-- feature -->
</testsuite> <!-- com.cucumber.framework.runner.Infotech_HR.forgot_runner -->
